<?xml version="1.0"?>
<robot name="rameno_jednoduche">

  <link name="base_link">
    <visual>
      <geometry>
        <cylinder length="0.01" radius="0.05"/>
      </geometry>
       <material name="white">
        <color rgba="1 1 1 1"/>
      </material>
    </visual>
  </link>

  
  
  <link name="klb1">
    <visual>
      <geometry>
       <sphere radius="0.03"/>
      </geometry>
     <material name="seda">
        <color rgba="0.2 0.2 0.2 1"/>
      </material>
        <origin xyz="0 0 0" rpy = "0 0 0"/>
    </visual>
  </link>
  
  


 <link name="klb2">
    <visual>
      <geometry>
       <sphere radius="0.03"/>
      </geometry>
   
      <material name="seda">
        <color rgba="0.2 0.2 0.2 1"/>
      </material>
      <origin xyz="0 0 0" rpy = "0 0 0"/>
    </visual>
  </link>

  
    
    <link name="klb3">
    <visual>
      <geometry>
       <sphere radius="0.03"/>
      </geometry>
   
      <material name="seda">
        <color rgba="0.2 0.2 0.2 1"/>
      </material>
      <origin xyz="0 0 0" rpy = "0 0 0"/>
    </visual>
  </link>
  
  <link name="link3">
    <visual>
      <geometry>
        <cylinder length="0.178" radius = "0.01"/>
      </geometry>
       <material name="white">
        <color rgba="1 1 1 1"/>
      </material>
      <origin xyz="0 0 0.089" rpy = "0 0 0"/>
    </visual>
  </link>
  
   <link name="link2">
    <visual>
      <geometry>
        <cylinder length="0.178" radius = "0.01"/>
      </geometry>
       <material name="white">
        <color rgba="1 1 1 1"/>
      </material>
      <origin xyz="0 0 0.089" rpy = "0 0 0"/>
    </visual>
  </link>
  
   <link name="link1">
    <visual>
      <geometry>
        <cylinder length="0.203" radius = "0.01"/>
      </geometry>
       <material name="white">
        <color rgba="1 1 1 1"/>
      </material>
       <origin xyz="0 0 0.1015" rpy = "0 0 0"/>
    </visual>
  </link>
  

  <joint name="base_link_joint" type="revolute">
   <axis xyz="0 0 1"/>
    <parent link="base_link"/>
    <child link="klb1"/>
     <origin xyz="0 0 0" rpy = "0 0 0"/>
      <limit effort="1000.0" lower="-1.62" upper="1.62" velocity="0.5"/>
  </joint>
  
  <joint name="joint1" type="revolute">
   <axis xyz="0 1 0"/>
    <parent link="klb1"/>
    <child link="klb2"/>
     <origin xyz="0 0 0.203" rpy = "0 0 0"/>
    <limit effort="1000.0" lower="-0.96" upper="2.182" velocity="0.5"/>
  </joint>
  
  <joint name="joint2" type="revolute">
   <axis xyz="0 1 0"/>
    <parent link="klb2"/>
    <child link="klb3"/>
     <origin xyz="0 0 0.178" rpy = "0 0 0"/>
    <limit effort="1000.0" lower="-0.96" upper="2.182" velocity="0.5"/>
  </joint>
  
   <joint name="link3_to_klb3" type="fixed">
   <axis xyz="0 1 0"/>
    <parent link="klb3"/>
    <child link="link3"/>
   <origin xyz="0 0 0" rpy = "0 0 0"/>
  </joint>
  
  <joint name="link2_to_klb2" type="fixed">
   <axis xyz="0 1 0"/>
    <parent link="klb2"/>
    <child link="link2"/>
   <origin xyz="0 0 0" rpy = "0 0 0"/>
  </joint>
  
   <joint name="link1_to_klb1" type="fixed">
   <axis xyz="0 1 0"/>
    <parent link="klb1"/>
    <child link="link1"/>
   <origin xyz="0 0 0" rpy = "0 0 0"/>
  </joint>


</robot>
