<?xml version="1.0"?>
<robot name="rameno_jednoduche">

  <link name="base_link">
    <visual>
      <geometry>
        <box size="0.05 0.05 0.05"/>
      </geometry>
       <material name="biela">
        <color rgba="1 1 1 1"/>
      </material>
    </visual>
    <collision>
        <geometry>
        <box size="0.05 0.05 0.05"/>
        </geometry>
     </collision>
  </link>


   <link name="link1">
    <visual>
      <geometry>
        <cylinder length="0.3" radius = "0.01"/>
      </geometry>
       <material name="modra">
        <color rgba="0.1 0.1 1 1"/>
      </material>
       <origin xyz="0 0 0.15" rpy = "0 0 0"/>
    </visual>
    <inertial>
      <mass value="10"/>
      <inertia ixx="0.4" ixy="0.0" ixz="0.0" iyy="0.4" iyz="0.0" izz="0.2"/>
    </inertial>
  </link>
  

  <joint name="base_link_joint" type="revolute">
   <axis xyz="0 1 0"/>
    <parent link="base_link"/>
    <child link="link1"/>
     <origin xyz="0 0 0" rpy = "0 0 0"/>
      <limit effort="1000.0" lower="-1.62" upper="1.62" velocity="0.5"/>
  </joint>
  

</robot>
